<?xml version="1.0" ?>
<!-- =================================================================================== -->
<!-- |    This document was autogenerated by xacro from kr3r540.xacro                  | -->
<!-- |    EDITING THIS FILE BY HAND IS NOT RECOMMENDED                                 | -->
<!-- =================================================================================== -->
<robot name="kuka_kr3r540" xmlns:controller="http://playerstage.sourceforge.net/gazebo/xmlschema/#controller" xmlns:interface="http://playerstage.sourceforge.net/gazebo/xmlschema/#interface" xmlns:sensor="http://playerstage.sourceforge.net/gazebo/xmlschema/#sensor">
  <!-- colours based on RAL values given in "FAQ - Colours of robot and robot
       controller", version "KUKA.Tifs | 2010-01-21 |YM| DefaultColorsRobotAndController.doc",
       downloaded 2015-07-18 from
       http://www.kuka.be/main/cservice/faqs/hardware/DefaultColorsRobotAndController.pdf

       all RAL colours converted using http://www.visual-graphics.de/en/customer-care/ral-colours
  -->
  <link name="base_link">
    <visual>
      <origin rpy="0 0 0" xyz="0 0 0"/>
      <geometry>
        <mesh filename="package://kuka_kr3_support/meshes/kr3r540/visual/base_link.stl"/>
      </geometry>
      <material name="">
        <color rgba="0.5058823529411764 0.47058823529411764 0.38823529411764707 1.0"/>
      </material>
    </visual>
    <collision>
      <origin rpy="0 0 0" xyz="0 0 0"/>
      <geometry>
        <mesh filename="package://kuka_kr3_support/meshes/kr3r540/collision/base_link.stl"/>
      </geometry>
      <inertial>
        <origin rpy="0 0 0" xyz="0 0 0"/>
        <mass value="8.45"/>
        <inertia ixx="0.09" ixy="0.0" ixz="-0.02" iyy="0.11" iyz="0.0" izz="0.05"/>
      </inertial>
    </collision>
  </link>
  <link name="link_1">
    <visual>
      <origin rpy="0 0 0" xyz="0 0 0"/>
      <geometry>
        <mesh filename="package://kuka_kr3_support/meshes/kr3r540/visual/link_1.stl"/>
      </geometry>
      <material name="">
        <color rgba="0.9450980392156862 0.9254901960784314 1.0 1.0"/>
      </material>
    </visual>
    <collision>
      <origin rpy="0 0 0" xyz="0 0 0"/>
      <geometry>
        <mesh filename="package://kuka_kr3_support/meshes/kr3r540/collision/link_1.stl"/>
      </geometry>
      <inertial>
        <origin rpy="0 0 0" xyz="0 0 0"/>
        <mass value="4.46"/>
        <inertia ixx="0.24" ixy="0.0" ixz="0.0" iyy="0.24" iyz="0.0" izz="0.02"/>
      </inertial>
    </collision>
  </link>
  <link name="link_2">
    <visual>
      <origin rpy="0 0 0" xyz="0 0 0"/>
      <geometry>
        <mesh filename="package://kuka_kr3_support/meshes/kr3r540/visual/link_2.stl"/>
      </geometry>
      <material name="">
        <color rgba="0.9450980392156862 0.9254901960784314 1.0 1.0"/>
      </material>
    </visual>
    <collision>
      <origin rpy="0 0 0" xyz="0 0 0"/>
      <geometry>
        <mesh filename="package://kuka_kr3_support/meshes/kr3r540/collision/link_2.stl"/>
      </geometry>
      <inertial>
        <origin rpy="0 0 0" xyz="0 0 0"/>
        <mass value="9.11"/>
        <inertia ixx="0.065" ixy="0.0" ixz="0.0" iyy="0.065" iyz="0.0" izz="0.02"/>
      </inertial>
    </collision>
  </link>
  <link name="link_3">
    <visual>
      <origin rpy="0 0 0" xyz="0 0 0"/>
      <geometry>
        <mesh filename="package://kuka_kr3_support/meshes/kr3r540/visual/link_3.stl"/>
      </geometry>
      <material name="">
        <color rgba="0.9450980392156862 0.9254901960784314 1.0 1.0"/>
      </material>
    </visual>
    <collision>
      <origin rpy="0 0 0" xyz="0 0 0"/>
      <geometry>
        <mesh filename="package://kuka_kr3_support/meshes/kr3r540/collision/link_3.stl"/>
      </geometry>
      <inertial>
        <origin rpy="0 0 0" xyz="0 0 0"/>
        <mass value="2.2"/>
        <inertia ixx="0.64" ixy="0.0" ixz="0.05" iyy="0.64" iyz="0.0" izz="0.01"/>
      </inertial>
    </collision>
  </link>
  <link name="link_4">
    <visual>
      <origin rpy="0 0 0" xyz="0 0 0"/>
      <geometry>
        <mesh filename="package://kuka_kr3_support/meshes/kr3r540/visual/link_4.stl"/>
      </geometry>
      <material name="">
        <color rgba="0.9450980392156862 0.9254901960784314 1.0 1.0"/>
      </material>
    </visual>
    <collision>
      <origin rpy="0 0 0" xyz="0 0 0"/>
      <geometry>
        <mesh filename="package://kuka_kr3_support/meshes/kr3r540/collision/link_4.stl"/>
      </geometry>
      <inertial>
        <origin rpy="0 0 0" xyz="0 0 0"/>
        <mass value="1.5"/>
        <inertia ixx="0.45" ixy="0.0" ixz="0.15" iyy="0.5" iyz="0.0" izz="0.05"/>
      </inertial>
    </collision>
  </link>
  <link name="link_5">
    <visual>
      <origin rpy="0 0 0" xyz="0 0 0"/>
      <geometry>
        <mesh filename="package://kuka_kr3_support/meshes/kr3r540/visual/link_5.stl"/>
      </geometry>
      <material name="">
        <color rgba="0.9450980392156862 0.9254901960784314 1.0 1.0"/>
      </material>
    </visual>
    <collision>
      <origin rpy="0 0 0" xyz="0 0 0"/>
      <geometry>
        <mesh filename="package://kuka_kr3_support/meshes/kr3r540/collision/link_5.stl"/>
      </geometry>
      <inertial>
        <origin rpy="0 0 0" xyz="0 0 0"/>
        <mass value="0.75"/>
        <inertia ixx="0.23" ixy="0.0" ixz="0.1" iyy="0.28" iyz="0.0" izz="0.05"/>
      </inertial>
    </collision>
  </link>
  <link name="link_6">
    <visual>
      <origin rpy="0 0 0" xyz="0 0 0"/>
      <geometry>
        <mesh filename="package://kuka_kr3_support/meshes/kr3r540/visual/link_6.stl"/>
      </geometry>
      <material name="">
        <color rgba="0.5058823529411764 0.47058823529411764 0.38823529411764707 1.0"/>
      </material>
    </visual>
    <collision>
      <origin rpy="0 0 0" xyz="0 0 0"/>
      <geometry>
        <mesh filename="package://kuka_kr3_support/meshes/kr3r540/collision/link_6.stl"/>
      </geometry>
    </collision>
    <inertial>
      <origin rpy="0 0 0" xyz="0 0 0"/>
      <mass value="0.026"/>
      <inertia ixx="0.01" ixy="0.0" ixz="0.0" iyy="0.01" iyz="0" izz="0"/>
    </inertial>
  </link>
  <!-- Following REP199, this frame shall be use to attach EEF or other equipment -->
  <link name="flange"/>
  <joint name="joint_a1" type="revolute">
    <origin rpy="0 0 0" xyz="0 0 0.345"/>
    <parent link="base_link"/>
    <child link="link_1"/>
    <axis xyz="0 0 -1"/>
    <limit effort="100" lower="-2.9670597283903604" upper="2.9670597283903604" velocity="9.250245035569947"/>
  </joint>
  <joint name="joint_a2" type="revolute">
    <origin rpy="0 0 0" xyz="0.020 0 0"/>
    <parent link="link_1"/>
    <child link="link_2"/>
    <axis xyz="0 1 0"/>
    <limit effort="100" lower="-2.9670597283903604" upper="0.8726646259971648" velocity="9.232791743050003"/>
  </joint>
  <joint name="joint_a3" type="revolute">
    <origin rpy="0 0 0" xyz="0.260 0 0"/>
    <parent link="link_2"/>
    <child link="link_3"/>
    <axis xyz="0 1 0"/>
    <limit effort="100" lower="-1.9198621771937625" upper="2.705260340591211" velocity="9.389871375729493"/>
  </joint>
  <joint name="joint_a4" type="revolute">
    <origin rpy="0 0 0" xyz="0 0 0.020"/>
    <parent link="link_3"/>
    <child link="link_4"/>
    <axis xyz="-1 0 0"/>
    <limit effort="100" lower="-3.0543261909900767" upper="3.0543261909900767" velocity="10.471975511965978"/>
  </joint>
  <joint name="joint_a5" type="revolute">
    <origin rpy="0 0 0" xyz="0.260 0 0"/>
    <parent link="link_4"/>
    <child link="link_5"/>
    <axis xyz="0 1 0"/>
    <limit effort="100" lower="-2.0943951023931953" upper="2.0943951023931953" velocity="10.471975511965978"/>
  </joint>
  <joint name="joint_a6" type="revolute">
    <origin rpy="0 0 0" xyz="0.075 0 0"/>
    <parent link="link_5"/>
    <child link="link_6"/>
    <axis xyz="-1 0 0"/>
    <limit effort="100" lower="-6.1086523819801535" upper="6.1086523819801535" velocity="13.962634015954636"/>
  </joint>
  <joint name="joint_a6-tool0" type="fixed">
    <parent link="link_6"/>
    <child link="flange"/>
    <origin rpy="0 0 0" xyz="0 0 0"/>
  </joint>
  <!-- ROS base_link to KUKA $ROBROOT coordinate system transform -->
  <link name="base"/>
  <joint name="base_link-base" type="fixed">
    <origin rpy="0 0 0" xyz="0 0 0"/>
    <parent link="base_link"/>
    <child link="base"/>
  </joint>
  <!-- This frame corresponds to the $TOOL coordinate system in KUKA KRC controllers -->
  <link name="tool0"/>
  <joint name="flange-tool0" type="fixed">
    <parent link="flange"/>
    <child link="tool0"/>
    <origin rpy="0 1.5707963267948966 0" xyz="0 0 0"/>
  </joint>
  <joint name="gripper_anterior_gripper_joint" type="fixed">
    <origin rpy="0 0 0" xyz="0 0 0"/>
    <parent link="tool0"/>
    <child link="base_link_gripper"/>
  </joint>
  <!-- BASE LINK -->
  <link
    name="base_link_gripper">
    <inertial>
      <origin
        xyz="-0.000798709905497759 0.0330041725900681 0.000181924965941612"
        rpy="0 -1.5708 0" />
      <mass
        value="3.0843E-05" />
      <inertia
        ixx="1.2175E-08"
        ixy="-1.7683E-12"
        ixz="3.118E-13"
        iyy="2.6196E-09"
        iyz="6.348E-12"
        izz="1.3073E-08" />
    </inertial>
    <visual>
      <origin
        xyz="0 0 0"
        rpy="0 -1.5708 0" />
      <geometry>
        <mesh
          filename="package://schunk_25nnb/meshes/base_link.STL" />
      </geometry>
      <material
        name="">
        <color
          rgba="1 1 1 1" />
      </material>
    </visual>
    <collision>
      <origin
        xyz="0 0 0"
        rpy="0 -1.5708 0" />
      <geometry>
        <mesh
          filename="package://schunk_25nnb/meshes/base_link.STL" />
      </geometry>
    </collision>
  </link>
  <link
    name="left_link">
    <inertial>
      <origin
        xyz="0.0054865 -0.0099792 0.0019878"
        rpy="1.5708 -1.5708 0" />
      <mass
        value="9.1881E-07" />
      <inertia
        ixx="2.3947E-11"
        ixy="-1.4195E-11"
        ixz="4.575E-12"
        iyy="4.2053E-11"
        iyz="4.362E-12"
        izz="5.6785E-11" />
    </inertial>
    <visual>
      <origin
        xyz="0 0 0"
        rpy="1.5708 -1.5708 0" />
      <geometry>
        <mesh
          filename="package://schunk_25nnb/meshes/left_link.STL" />
      </geometry>
      <material
        name="">
        <color
          rgba="1 1 1 1" />
      </material>
    </visual>
    <collision>
      <origin
        xyz="0 0 0"
        rpy="1.5708 -1.5708 0" />
      <geometry>
        <mesh
          filename="package://schunk_25nnb/meshes/left_link.STL" />
      </geometry>
    </collision>
  </link>
  <joint
    name="joint_left"
    type="prismatic">
    <origin
      xyz="0 -8.2944E-05 0.08056"
      rpy="0 0 0" />
    <parent
      link="base_link_gripper" />
    <child
      link="left_link" />
    <axis
      xyz="1 0 0" />
    <limit
      lower="-0.0047"
      upper="0.000"
      effort="20.00001"
      velocity="2.00001" />
  </joint>
  <link
    name="right_link">
    <inertial>
      <origin
        xyz="0.0039401 -0.0099792 0.0021878"
        rpy="1.5708 -1.5708 0" />
      <mass
        value="9.1881E-07" />
      <inertia
        ixx="2.3947E-11"
        ixy="-1.4195E-11"
        ixz="4.575E-12"
        iyy="4.2053E-11"
        iyz="4.362E-12"
        izz="5.6785E-11" />
    </inertial>
    <visual>
      <origin
        xyz="0 0 0"
        rpy="1.5708 -1.5708 0" />
      <geometry>
        <mesh
          filename="package://schunk_25nnb/meshes/right_link.STL" />
      </geometry>
      <material
        name="">
        <color
          rgba="1 1 1 1" />
      </material>
    </visual>
    <collision>
      <origin
        xyz="0 0 0"
        rpy="1.5708 -1.5708 0" />
      <geometry>
        <mesh
          filename="package://schunk_25nnb/meshes/right_link.STL" />
      </geometry>
    </collision>
  </link>
  <joint
    name="joint_right"
    type="prismatic">
    <origin
      xyz="0 -8.2944E-05 0.08056"
      rpy="0 0 0" />
    <parent
      link="base_link_gripper" />
    <child
      link="right_link" />
    <axis
      xyz="1 0 0" />
    <limit
      lower="-0.0047"
      upper="0.00001"
      effort="20.00001"
      velocity="2.00001" />
  </joint>
</robot>
