<?xml version="1.0" encoding="utf-8"?>
<!-- This URDF was automatically created by SolidWorks to URDF Exporter! Originally created by Stephen Brawner (brawner@gmail.com) 
     Commit Version: 1.6.0-4-g7f85cfe  Build Version: 1.6.7995.38578
     For more information, please see http://wiki.ros.org/sw_urdf_exporter -->
<robot
  name="schunk_25nnb">
  <link
    name="base_link">
    <inertial>
      <origin
        xyz="-0.00079871 -0.00018192 0.033004"
        rpy="0 0 0" />
      <mass
        value="3.0843E-05" />
      <inertia
        ixx="1.2175E-08"
        ixy="-3.118E-13"
        ixz="-1.7683E-12"
        iyy="1.3073E-08"
        iyz="-6.348E-12"
        izz="2.6196E-09" />
    </inertial>
    <visual>
      <origin
        xyz="0 0 0"
        rpy="0 0 0" />
      <geometry>
        <mesh
          filename="package://schunk_25nnb/meshes/base_link.STL" />
      </geometry>
      <material
        name="">
        <color
          rgba="1 0 0 1" />
      </material>
    </visual>
    <collision>
      <origin
        xyz="0 0 0"
        rpy="0 0 0" />
      <geometry>
        <mesh
          filename="package://schunk_25nnb/meshes/base_link.STL" />
      </geometry>
    </collision>
  </link>
  <link
    name="left_link">
    <inertial>
      <origin
        xyz="0.057126 0.053896 -4.4848E-07"
        rpy="0 0 0" />
      <mass
        value="0.016862" />
      <inertia
        ixx="3.4651E-05"
        ixy="-5.3642E-06"
        ixz="6.1325E-11"
        iyy="3.9057E-06"
        iyz="7.4564E-10"
        izz="3.7772E-05" />
    </inertial>
    <visual>
      <origin
        xyz="0 0 0"
        rpy="0 0 0" />
      <geometry>
        <mesh
          filename="package://schunk_25nnb/meshes/left_link.STL" />
      </geometry>
      <material
        name="">
        <color
          rgba="1 0 0 1" />
      </material>
    </visual>
    <collision>
      <origin
        xyz="0 0 0"
        rpy="0 0 0" />
      <geometry>
        <mesh
          filename="package://schunk_25nnb/meshes/left_link.STL" />
      </geometry>
    </collision>
  </link>
  <joint
    name="joint_left"
    type="prismatic">
    <origin
      xyz="0 -8.2944E-05 0.08056"
      rpy="1.5708 0 -3.1416" />
    <parent
      link="base_link" />
    <child
      link="left_link" />
    <axis
      xyz="1 0 0" />
    <limit
      lower="-0.0047"
      upper="1E-05"
      effort="20"
      velocity="2" />
  </joint>
  <link
    name="right_link">
    <inertial>
      <origin
        xyz="0.05558 0.053894 0.00070479"
        rpy="0 0 0" />
      <mass
        value="0.016862" />
      <inertia
        ixx="3.4651E-05"
        ixy="-5.364E-06"
        ixz="-4.675E-08"
        iyy="3.9083E-06"
        iyz="-2.9478E-07"
        izz="3.7769E-05" />
    </inertial>
    <visual>
      <origin
        xyz="0 0 0"
        rpy="0 0 0" />
      <geometry>
        <mesh
          filename="package://schunk_25nnb/meshes/right_link.STL" />
      </geometry>
      <material
        name="">
        <color
          rgba="1 0 0 1" />
      </material>
    </visual>
    <collision>
      <origin
        xyz="0 0 0"
        rpy="0 0 0" />
      <geometry>
        <mesh
          filename="package://schunk_25nnb/meshes/right_link.STL" />
      </geometry>
    </collision>
  </link>
  <joint
    name="joint_right"
    type="prismatic">
    <origin
      xyz="0 -8.2944E-05 0.08056"
      rpy="1.5708 0 0" />
    <parent
      link="base_link" />
    <child
      link="right_link" />
    <axis
      xyz="1 0 0" />
    <limit
      lower="-0.0047"
      upper="1E-05"
      effort="20"
      velocity="2" />
  </joint>
</robot>