<?xml version="1.0" encoding="utf-8"?>
<!-- This URDF was automatically created by SolidWorks to URDF Exporter! Originally created by Stephen Brawner (brawner@gmail.com) 
     Commit Version: 1.6.0-4-g7f85cfe  Build Version: 1.6.7995.38578
     For more information, please see http://wiki.ros.org/sw_urdf_exporter -->
<robot
  name="schunk_25nnb">
  <link
    name="base_link">
    <inertial>
      <origin
        xyz="0.0332072546842129 0.000470034112707346 -0.00109299234976048"
        rpy="0 0 0" />
      <mass
        value="0.03199945156995" />
      <inertia
        ixx="2.6340948711181E-06"
        ixy="-6.34796243387625E-09"
        ixz="1.79619163453797E-09"
        iyy="1.30867625733723E-05"
        iyz="3.1167286357459E-10"
        izz="1.21892803474127E-05" />
    </inertial>
    <visual>
      <origin
        xyz="0 0 0"
        rpy="0 0 0" />
      <geometry>
        <mesh
          filename="package://schunk_25nnb/meshes/base_link.STL" />
      </geometry>
      <material
        name="">
        <color
          rgba="0.792156862745098 0.819607843137255 0.933333333333333 1" />
      </material>
    </visual>
    <collision>
      <origin
        xyz="0 0 0"
        rpy="0 0 0" />
      <geometry>
        <mesh
          filename="package://schunk_25nnb/meshes/base_link.STL" />
      </geometry>
    </collision>
  </link>
  <link
    name="right_link">
    <inertial>
      <origin
        xyz="0.051256 0.052457 0.00047325"
        rpy="0 0 0" />
      <mass
        value="0.028333" />
      <inertia
        ixx="8.159E-06"
        ixy="-1.0398E-05"
        ixz="-5.3309E-09"
        iyy="5.2271E-05"
        iyz="-4.9924E-09"
        izz="5.8885E-05" />
    </inertial>
    <visual>
      <origin
        xyz="0 0 0"
        rpy="0 0 0" />
      <geometry>
        <mesh
          filename="package://schunk_25nnb/meshes/right_link.STL" />
      </geometry>
      <material
        name="">
        <color
          rgba="0.79216 0.81961 0.93333 1" />
      </material>
    </visual>
    <collision>
      <origin
        xyz="0 0 0"
        rpy="0 0 0" />
      <geometry>
        <mesh
          filename="package://schunk_25nnb/meshes/right_link.STL" />
      </geometry>
    </collision>
  </link>
  <joint
    name="joint_right"
    type="prismatic">
    <origin
      xyz="0 0 0"
      rpy="0 0 0" />
    <parent
      link="base_link" />
    <child
      link="right_link" />
    <axis
      xyz="0 1 0" />
    <limit
      lower="-0.003"
      upper="0"
      effort="40"
      velocity="2" />
  </joint>
  <link
    name="left_link">
    <inertial>
      <origin
        xyz="0.051299 -0.053646 0.00083662"
        rpy="0 0 0" />
      <mass
        value="0.028312" />
      <inertia
        ixx="8.1587E-06"
        ixy="1.0398E-05"
        ixz="5.3309E-09"
        iyy="5.2271E-05"
        iyz="-4.9924E-09"
        izz="5.8885E-05" />
    </inertial>
    <visual>
      <origin
        xyz="0 0 0"
        rpy="0 0 0" />
      <geometry>
        <mesh
          filename="package://schunk_25nnb/meshes/left_link.STL" />
      </geometry>
      <material
        name="">
        <color
          rgba="0.79216 0.81961 0.93333 1" />
      </material>
    </visual>
    <collision>
      <origin
        xyz="0 0 0"
        rpy="0 0 0" />
      <geometry>
        <mesh
          filename="package://schunk_25nnb/meshes/left_link.STL" />
      </geometry>
    </collision>
  </link>
  <joint
    name="joint_left"
    type="prismatic">
    <origin
      xyz="0 0 0"
      rpy="0 0 0" />
    <parent
      link="base_link" />
    <child
      link="left_link" />
    <axis
      xyz="0 1 0" />
    <limit
      lower="-0.003"
      upper="0"
      effort="40"
      velocity="2" />
  </joint>
</robot>