<?xml version="1.0" ?>
<!-- =================================================================================== -->
<!-- |    This document was autogenerated by xacro from kr4r600.xacro                  | -->
<!-- |    EDITING THIS FILE BY HAND IS NOT RECOMMENDED                                 | -->
<!-- =================================================================================== -->
<robot name="kuka_kr4r600">
  <!-- colours based on RAL values given in "FAQ - Colours of robot and robot
       controller", version "KUKA.Tifs | 2010-01-21 |YM| DefaultColorsRobotAndController.doc",
       downloaded 2015-07-18 from
       http://www.kuka.be/main/cservice/faqs/hardware/DefaultColorsRobotAndController.pdf

       all RAL colours converted using http://www.visual-graphics.de/en/customer-care/ral-colours
  -->
  <link name="base_link">
    <visual>
      <origin rpy="0 0 0" xyz="0 0 0"/>
      <geometry>
        <mesh filename="package://kuka_kr4_support/meshes/kr4r600/visual/base_link.stl"/>
      </geometry>
      <material name="">
        <color rgba="0.5058823529411764 0.47058823529411764 0.38823529411764707 1.0"/>
      </material>
    </visual>
    <collision>
      <origin rpy="0 0 0" xyz="0 0 0"/>
      <geometry>
        <mesh filename="package://kuka_kr4_support/meshes/kr4r600/collision/base_link.stl"/>
      </geometry>
      <inertial>
        <origin rpy="0 0 0" xyz="0 0 0"/>
        <mass value="6.64"/>
        <inertia ixx="0.11" ixy="0.0" ixz="-0.02" iyy="0.06" iyz="-0.02" izz="0.08"/>
      </inertial>
    </collision>
  </link>
  <link name="link_1">
    <visual>
      <origin rpy="0 0 0" xyz="0 0 0"/>
      <geometry>
        <mesh filename="package://kuka_kr4_support/meshes/kr4r600/visual/link_1.stl"/>
      </geometry>
      <material name="">
        <color rgba="0.9450980392156862 0.9254901960784314 1.0 1.0"/>
      </material>
    </visual>
    <collision>
      <origin rpy="0 0 0" xyz="0 0 0"/>
      <geometry>
        <mesh filename="package://kuka_kr4_support/meshes/kr4r600/collision/link_1.stl"/>
      </geometry>
      <inertial>
        <origin rpy="0 0 0" xyz="0 0 0"/>
        <mass value="3.49"/>
        <inertia ixx="0.25" ixy="0.0" ixz="-0.02" iyy="0.02" iyz="0.0" izz="0.26"/>
      </inertial>
    </collision>
  </link>
  <link name="link_2">
    <visual>
      <origin rpy="0 0 0" xyz="0 0 0"/>
      <geometry>
        <mesh filename="package://kuka_kr4_support/meshes/kr4r600/visual/link_2.stl"/>
      </geometry>
      <material name="">
        <color rgba="0.9450980392156862 0.9254901960784314 1.0 1.0"/>
      </material>
    </visual>
    <collision>
      <origin rpy="0 0 0" xyz="0 0 0"/>
      <geometry>
        <mesh filename="package://kuka_kr4_support/meshes/kr4r600/collision/link_2.stl"/>
      </geometry>
      <inertial>
        <origin rpy="0 0 0" xyz="0 0 0"/>
        <mass value="4.73"/>
        <inertia ixx="1" ixy="0.01" ixz="-0.02" iyy="0.02" iyz="-0.05" izz="1"/>
      </inertial>
    </collision>
  </link>
  <link name="link_3">
    <visual>
      <origin rpy="0 0 0" xyz="0 0 0"/>
      <geometry>
        <mesh filename="package://kuka_kr4_support/meshes/kr4r600/visual/link_3.stl"/>
      </geometry>
      <material name="">
        <color rgba="0.9450980392156862 0.9254901960784314 1.0 1.0"/>
      </material>
    </visual>
    <collision>
      <origin rpy="0 0 0" xyz="0 0 0"/>
      <geometry>
        <mesh filename="package://kuka_kr4_support/meshes/kr4r600/collision/link_3.stl"/>
      </geometry>
      <inertial>
        <origin rpy="0 0 0" xyz="0 0 0"/>
        <mass value="2.14"/>
        <inertia ixx="0.85" ixy="0.0" ixz="-0.02" iyy="0.01" iyz="0.03" izz="0.84"/>
      </inertial>
    </collision>
  </link>
  <link name="link_4">
    <visual>
      <origin rpy="0 0 0" xyz="0 0 0"/>
      <geometry>
        <mesh filename="package://kuka_kr4_support/meshes/kr4r600/visual/link_4.stl"/>
      </geometry>
      <material name="">
        <color rgba="0.9450980392156862 0.9254901960784314 1.0 1.0"/>
      </material>
    </visual>
    <collision>
      <origin rpy="0 0 0" xyz="0 0 0"/>
      <geometry>
        <mesh filename="package://kuka_kr4_support/meshes/kr4r600/collision/link_4.stl"/>
      </geometry>
      <inertial>
        <origin rpy="0 0 0" xyz="0 0 0"/>
        <mass value="1.1"/>
        <inertia ixx="0.49" ixy="-0.03" ixz="-0.01" iyy="0.05" iyz="0.14" izz="0.45"/>
      </inertial>
    </collision>
  </link>
  <link name="link_5">
    <visual>
      <origin rpy="0 0 0" xyz="0 0 0"/>
      <geometry>
        <mesh filename="package://kuka_kr4_support/meshes/kr4r600/visual/link_5.stl"/>
      </geometry>
      <material name="">
        <color rgba="0.9450980392156862 0.9254901960784314 1.0 1.0"/>
      </material>
    </visual>
    <collision>
      <origin rpy="0 0 0" xyz="0 0 0"/>
      <geometry>
        <mesh filename="package://kuka_kr4_support/meshes/kr4r600/collision/link_5.stl"/>
      </geometry>
      <inertial>
        <origin rpy="0 0 0" xyz="0 0 0"/>
        <mass value="0.54"/>
        <inertia ixx="0.26" ixy="-0.02" ixz="-0.01" iyy="0.04" iyz="0.1" izz="0.22"/>
      </inertial>
    </collision>
  </link>
  <link name="link_6">
    <visual>
      <origin rpy="0 0 0" xyz="0 0 0"/>
      <geometry>
        <mesh filename="package://kuka_kr4_support/meshes/kr4r600/visual/link_6.stl"/>
      </geometry>
      <material name="">
        <color rgba="0.5058823529411764 0.47058823529411764 0.38823529411764707 1.0"/>
      </material>
    </visual>
    <collision>
      <origin rpy="0 0 0" xyz="0 0 0"/>
      <geometry>
        <mesh filename="package://kuka_kr4_support/meshes/kr4r600/collision/link_6.stl"/>
      </geometry>
      <inertial>
        <origin rpy="0 0 0" xyz="0 0 0"/>
        <mass value="0.03"/>
        <inertia ixx="0.02" ixy="0.0" ixz="-0.02" iyy="0.11" iyz="0.01" izz="0.01"/>
      </inertial>
    </collision>
  </link>
  <!-- This frame corresponds to the $FLANGE coordinate system in KUKA KRC controllers. -->
  <link name="tool0"/>
  <joint name="joint_a1" type="revolute">
    <origin rpy="0 0 0" xyz="0 0 0.33"/>
    <parent link="base_link"/>
    <child link="link_1"/>
    <axis xyz="0 0 -1"/>
    <limit effort="0" lower="-2.9670597283903604" upper="2.9670597283903604" velocity="9.250245035569947"/>
  </joint>
  <joint name="joint_a2" type="revolute">
    <origin rpy="0 0 0" xyz="0 0 0"/>
    <parent link="link_1"/>
    <child link="link_2"/>
    <axis xyz="0 1 0"/>
    <limit effort="0" lower="-3.4033920413889427" upper="0.6981317007977318" velocity="9.232791743050003"/>
  </joint>
  <joint name="joint_a3" type="revolute">
    <origin rpy="0 0 0" xyz="0.290 0 0"/>
    <parent link="link_2"/>
    <child link="link_3"/>
    <axis xyz="0 1 0"/>
    <limit effort="0" lower="-2.007128639793479" upper="2.6179938779914944" velocity="9.389871375729493"/>
  </joint>
  <joint name="joint_a4" type="revolute">
    <origin rpy="0 0 0" xyz="0.310 0 0.020"/>
    <parent link="link_3"/>
    <child link="link_4"/>
    <axis xyz="-1 0 0"/>
    <limit effort="0" lower="-3.2288591161895095" upper="3.2288591161895095" velocity="10.471975511965978"/>
  </joint>
  <joint name="joint_a5" type="revolute">
    <origin rpy="0 0 0" xyz="0 0 0"/>
    <parent link="link_4"/>
    <child link="link_5"/>
    <axis xyz="0 1 0"/>
    <limit effort="0" lower="-2.0943951023931953" upper="2.0943951023931953" velocity="10.471975511965978"/>
  </joint>
  <joint name="joint_a6" type="revolute">
    <origin rpy="0 0 0" xyz="0.075 0 0"/>
    <parent link="link_5"/>
    <child link="link_6"/>
    <axis xyz="-1 0 0"/>
    <limit effort="0" lower="-6.1086523819801535" upper="6.1086523819801535" velocity="13.962634015954636"/>
  </joint>
  <joint name="joint_a6-tool0" type="fixed">
    <parent link="link_6"/>
    <child link="tool0"/>
    <origin rpy="0 1.5707963267948966 0" xyz="0 0 0"/>
  </joint>
  <!-- ROS base_link to KUKA $ROBROOT coordinate system transform -->
  <link name="base"/>
  <joint name="base_link-base" type="fixed">
    <origin rpy="0 0 0" xyz="0 0 0"/>
    <parent link="base_link"/>
    <child link="base"/>
  </joint>
</robot>

